<robot name="iCubHeidelberg01_SIM_MODEL">
  <link name="base_link" />

  <joint name="base_fixed_joint" type="fixed">
    <parent link="base_link" />
    <child  link="root_link" />
    <origin xyz="0 0 0" rpy="0 0 0" />
  </joint>

  <link name="root_link">
    <inertial>
      <origin xyz="-0.000175548 -0.0820671 -0.0679103" rpy="0 0 0"/>
      <mass value="4.55132"/>
      <inertia ixx="0.0133835" ixy="3.22057e-05" ixz="-6.77957e-05" iyy="0.0178931" iyz="-0.00175809" izz="0.020903"/>
    </inertial>
    <visual>
      <origin xyz="0 0 0" rpy="0 0 0"/>
      <geometry>
        <mesh filename="model://iCubHeidelberg01_model/dae_meshes/sim_sea_root_link_prt.dae" scale="0.001 0.001 0.001"/>
      </geometry>
      <material name="green">
        <color rgba="0 1 0 1"/>
      </material>
    </visual>
    <collision>
      <origin xyz="0 0 0" rpy="0 0 0"/>
      <geometry>
        <mesh filename="model://iCubHeidelberg01_model/dae_meshes/sim_sea_root_link_prt.dae" scale="0.001 0.001 0.001"/>
      </geometry>
    </collision>
  </link>
  <link name="SCSYS_EMS_ACCEL"/>
  <joint name="SCSYS_EMS_ACCEL_fixed_joint" type="fixed">
    <origin xyz="0.0125771 -0.147691 -0.0857308" rpy="3.14159265359 -0.279252281769 -1.57079632679"/>
    <parent link="root_link"/>
    <child link="SCSYS_EMS_ACCEL"/>
    <dynamics damping="0.1"/>
  </joint>
  <link name="SCSYS_EMS_GYRO"/>
  <joint name="SCSYS_EMS_GYRO_fixed_joint" type="fixed">
    <origin xyz="0.013081 -0.152086 -0.0844705" rpy="3.14159265359 -0.279252281769 -1.57079632679"/>
    <parent link="root_link"/>
    <child link="SCSYS_EMS_GYRO"/>
    <dynamics damping="0.1"/>
  </joint>
  <link name="SCSYS_EMS_GYRO_1"/>
  <joint name="SCSYS_EMS_GYRO_1_fixed_joint" type="fixed">
    <origin xyz="0.013081 -0.152086 -0.0844705" rpy="3.14159265359 -0.279252281769 -1.57079632679"/>
    <parent link="root_link"/>
    <child link="SCSYS_EMS_GYRO_1"/>
    <dynamics damping="0.1"/>
  </joint>
  <link name="SCSYS_EMS_ACCEL_1"/>
  <joint name="SCSYS_EMS_ACCEL_1_fixed_joint" type="fixed">
    <origin xyz="0.013081 -0.152086 -0.0844705" rpy="3.14159265359 -0.279252281769 -1.57079632679"/>
    <parent link="root_link"/>
    <child link="SCSYS_EMS_ACCEL_1"/>
    <dynamics damping="0.1"/>
  </joint>
  <link name="r_hip_1">
    <inertial>
      <origin xyz="-0.0344199 -2.6e-05 -0.0002121" rpy="0 0 0"/>
      <mass value="0.610394"/>
      <inertia ixx="0.000304601" ixy="7.97583e-07" ixz="-2.29911e-07" iyy="0.000454222" iyz="1.14938e-06" izz="0.000453573"/>
    </inertial>
    <visual>
      <origin xyz="0.0262461 0.151913 0.0428515000001" rpy="0 0 0"/>
      <geometry>
        <mesh filename="model://iCubHeidelberg01_model/dae_meshes/sim_sea_r_hip_1_prt.dae" scale="0.001 0.001 0.001"/>
      </geometry>
      <material name="black">
        <color rgba="0 0 0 1"/>
      </material>
    </visual>
    <collision>
      <origin xyz="0.0262461 0.151913 0.0428515000001" rpy="0 0 0"/>
      <geometry>
        <mesh filename="model://iCubHeidelberg01_model/dae_meshes/sim_sea_r_hip_1_prt.dae" scale="0.001 0.001 0.001"/>
      </geometry>
    </collision>
  </link>
  <joint name="r_hip_pitch" type="revolute">
    <origin xyz="-0.0262461 -0.151913 -0.0428515" rpy="0 0 0"/>
    <axis xyz="-1.0 -0.0 -0.0"/>
    <parent link="root_link"/>
    <child link="r_hip_1"/>
    <limit effort="50000" lower="-0.523598775598" upper="1.4835298642" velocity="50000"/>
    <dynamics damping="0.223"/>
  </joint>
  <link name="r_hip_2">
    <inertial>
      <origin xyz="-1.5e-06 -0.03665 0.0231604" rpy="0 0 0"/>
      <mass value="0.292811"/>
      <inertia ixx="0.000410194" ixy="1.58042e-08" ixz="6.95352e-09" iyy="0.000232087" iyz="2.60468e-05" izz="0.000252169"/>
    </inertial>
    <visual>
      <origin xyz="0.0701 0.151913 0.0690985998094" rpy="0 0 0"/>
      <geometry>
        <mesh filename="model://iCubHeidelberg01_model/dae_meshes/sim_sea_r_hip_2_prt.dae" scale="0.001 0.001 0.001"/>
      </geometry>
      <material name="red">
        <color rgba="1 0 0 1"/>
      </material>
    </visual>
    <collision>
      <origin xyz="0.0701 0.151913 0.0690985998094" rpy="0 0 0"/>
      <geometry>
        <mesh filename="model://iCubHeidelberg01_model/dae_meshes/sim_sea_r_hip_2_prt.dae" scale="0.001 0.001 0.001"/>
      </geometry>
    </collision>
  </link>
  <joint name="r_hip_roll" type="revolute">
    <origin xyz="-0.0438539 0 -0.0262471" rpy="0 0 0"/>
    <axis xyz="0.0 0.0 -1.0"/>
    <parent link="r_hip_1"/>
    <child link="r_hip_2"/>
    <limit effort="50000" lower="0.0" upper="1.57079632679" velocity="50000"/>
    <dynamics damping="0.223"/>
  </joint>
  <link name="r_upper_thigh">
    <inertial>
      <origin xyz="-0.0699184 -0.234474 -0.0438122998094" rpy="0 0 0"/>
      <mass value="0.122687"/>
      <inertia ixx="3.09316e-05" ixy="2.08202e-07" ixz="-1.99589e-08" iyy="5.53314e-05" iyz="9.22295e-09" izz="3.08107e-05"/>
    </inertial>
    <visual>
      <origin xyz="0 0 0" rpy="0 0 0"/>
      <geometry>
        <mesh filename="model://iCubHeidelberg01_model/dae_meshes/sim_sea_r_upper_thigh_prt.dae" scale="0.001 0.001 0.001"/>
      </geometry>
      <material name="blue">
        <color rgba="0 0 1 1"/>
      </material>
    </visual>
    <collision>
      <origin xyz="0 0 0" rpy="0 0 0"/>
      <geometry>
        <mesh filename="model://iCubHeidelberg01_model/dae_meshes/sim_sea_r_upper_thigh_prt.dae" scale="0.001 0.001 0.001"/>
      </geometry>
    </collision>
  </link>
  <joint name="r_leg_ft_sensor" type="fixed">
    <origin xyz="0.0701 0.151913 0.0690985998094" rpy="0 0 0"/>
    <parent link="r_hip_2"/>
    <child link="r_upper_thigh"/>
    <dynamics damping="0.1"/>
  </joint>
  <link name="r_thigh">
    <inertial>
      <origin xyz="-0.0001448 -0.065088 0.0091078" rpy="0 0 0"/>
      <mass value="2.82909"/>
      <inertia ixx="0.00961828" ixy="0.000277522" ixz="7.45373e-06" iyy="0.00385108" iyz="-0.000180645" izz="0.00968964"/>
    </inertial>
    <visual>
      <origin xyz="0.0701 0.241013 0.0437089998094" rpy="0 0 0"/>
      <geometry>
        <mesh filename="model://iCubHeidelberg01_model/dae_meshes/sim_sea_r_thigh_prt.dae" scale="0.001 0.001 0.001"/>
      </geometry>
      <material name="yellow">
        <color rgba="1 1 0 1"/>
      </material>
    </visual>
    <collision>
      <origin xyz="0.0701 0.241013 0.0437089998094" rpy="0 0 0"/>
      <geometry>
        <mesh filename="model://iCubHeidelberg01_model/dae_meshes/sim_sea_r_thigh_prt.dae" scale="0.001 0.001 0.001"/>
      </geometry>
    </collision>
  </link>
  <joint name="r_hip_yaw" type="revolute">
    <origin xyz="-0.0701 -0.244213 -0.0437089998094" rpy="0 0 0"/>
    <axis xyz="0.0 -1.0 0.0"/>
    <parent link="r_upper_thigh"/>
    <child link="r_thigh"/>
    <limit effort="50000" lower="-1.2217304764" upper="1.2217304764" velocity="50000"/>
    <dynamics damping="0.223"/>
  </joint>
  <link name="SCSYS_EMS_ACCEL0"/>
  <joint name="SCSYS_EMS_ACCEL0_fixed_joint" type="fixed">
    <origin xyz="0.0404072 -0.040027 -0.0125751" rpy="1.57079632679 0 1.57079632679"/>
    <parent link="r_thigh"/>
    <child link="SCSYS_EMS_ACCEL0"/>
    <dynamics damping="0.1"/>
  </joint>
  <link name="SCSYS_EMS_GYRO0"/>
  <joint name="SCSYS_EMS_GYRO0_fixed_joint" type="fixed">
    <origin xyz="0.0404072 -0.035455 -0.013079" rpy="1.57079632679 0 1.57079632679"/>
    <parent link="r_thigh"/>
    <child link="SCSYS_EMS_GYRO0"/>
    <dynamics damping="0.1"/>
  </joint>
  <link name="SCSYS_EMS_ACCEL_10"/>
  <joint name="SCSYS_EMS_ACCEL_10_fixed_joint" type="fixed">
    <origin xyz="-0.040407 -0.083207 -0.0125771" rpy="1.57079632679 0 -1.57079632679"/>
    <parent link="r_thigh"/>
    <child link="SCSYS_EMS_ACCEL_10"/>
    <dynamics damping="0.1"/>
  </joint>
  <link name="SCSYS_EMS_GYRO_10"/>
  <joint name="SCSYS_EMS_GYRO_10_fixed_joint" type="fixed">
    <origin xyz="-0.040407 -0.087779 -0.013081" rpy="1.57079632679 0 -1.57079632679"/>
    <parent link="r_thigh"/>
    <child link="SCSYS_EMS_GYRO_10"/>
    <dynamics damping="0.1"/>
  </joint>
  <link name="SCSYS_MTB_ACCEL"/>
  <joint name="SCSYS_MTB_ACCEL_fixed_joint" type="fixed">
    <origin xyz="0.0414996 -0.011459 0.03416985" rpy="-1.18682376736 0.000365167547861 -1.57082213412"/>
    <parent link="r_thigh"/>
    <child link="SCSYS_MTB_ACCEL"/>
    <dynamics damping="0.1"/>
  </joint>
  <link name="SCSYS_MTB_ACCEL_1"/>
  <joint name="SCSYS_MTB_ACCEL_1_fixed_joint" type="fixed">
    <origin xyz="0.0162386 -0.026366 -0.0437518" rpy="3.14159260377 0.000429089990404 -1.57091243007"/>
    <parent link="r_thigh"/>
    <child link="SCSYS_MTB_ACCEL_1"/>
    <dynamics damping="0.1"/>
  </joint>
  <link name="SCSYS_MTB_ACCEL_2"/>
  <joint name="SCSYS_MTB_ACCEL_2_fixed_joint" type="fixed">
    <origin xyz="-0.0157594 -0.026365 -0.0437518" rpy="3.14159265359 0.000429089993416 -1.57079632679"/>
    <parent link="r_thigh"/>
    <child link="SCSYS_MTB_ACCEL_2"/>
    <dynamics damping="0.1"/>
  </joint>
  <link name="SCSYS_MTB_ACCEL_3"/>
  <joint name="SCSYS_MTB_ACCEL_3_fixed_joint" type="fixed">
    <origin xyz="-0.049485 -0.064411 0.0117282" rpy="1.57079632679 0.000312931026869 -1.57079632679"/>
    <parent link="r_thigh"/>
    <child link="SCSYS_MTB_ACCEL_3"/>
    <dynamics damping="0.1"/>
  </joint>
  <link name="SCSYS_MTB_ACCEL_4"/>
  <joint name="SCSYS_MTB_ACCEL_4_fixed_joint" type="fixed">
    <origin xyz="-0.031565 0.042526 0.04206438" rpy="0.837758053214 0.000342816436844 -1.57071863125"/>
    <parent link="r_thigh"/>
    <child link="SCSYS_MTB_ACCEL_4"/>
    <dynamics damping="0.1"/>
  </joint>
  <link name="SCSYS_MTB_ACCEL_5"/>
  <joint name="SCSYS_MTB_ACCEL_5_fixed_joint" type="fixed">
    <origin xyz="-0.0083839 0.032642 0.05341396" rpy="0.26179934248 0.000399026344981 -1.5706841771"/>
    <parent link="r_thigh"/>
    <child link="SCSYS_MTB_ACCEL_5"/>
    <dynamics damping="0.1"/>
  </joint>
  <link name="SCSYS_MTB_ACCEL_6"/>
  <joint name="SCSYS_MTB_ACCEL_6_fixed_joint" type="fixed">
    <origin xyz="-0.0150686 -0.002429 0.0538284" rpy="0 0.000429089990404 -1.57068022352"/>
    <parent link="r_thigh"/>
    <child link="SCSYS_MTB_ACCEL_6"/>
    <dynamics damping="0.1"/>
  </joint>
  <link name="SCSYS_MTB_ACCEL_7"/>
  <joint name="SCSYS_MTB_ACCEL_7_fixed_joint" type="fixed">
    <origin xyz="0.0144314 -0.002429 0.0538284" rpy="0 0.000429089990404 -1.57068022352"/>
    <parent link="r_thigh"/>
    <child link="SCSYS_MTB_ACCEL_7"/>
    <dynamics damping="0.1"/>
  </joint>
  <link name="r_shank">
    <inertial>
      <origin xyz="0.0120744 -0.083027 0.0073589" rpy="0 0 0"/>
      <mass value="3.31111"/>
      <inertia ixx="0.0108069" ixy="0.000604622" ixz="5.98023e-06" iyy="0.00495004" iyz="-0.000693558" izz="0.0116311"/>
    </inertial>
    <visual>
      <origin xyz="0.0841895 0.386638 0.0437089998094" rpy="0 0 0"/>
      <geometry>
        <mesh filename="model://iCubHeidelberg01_model/dae_meshes/sim_sea_r_shank_prt.dae" scale="0.001 0.001 0.001"/>
      </geometry>
      <material name="pink">
        <color rgba="1 0 1 1"/>
      </material>
    </visual>
    <collision>
      <origin xyz="0.0841895 0.386638 0.0437089998094" rpy="0 0 0"/>
      <geometry>
        <mesh filename="model://iCubHeidelberg01_model/dae_meshes/sim_sea_r_shank_prt.dae" scale="0.001 0.001 0.001"/>
      </geometry>
    </collision>
  </link>
  <joint name="r_knee" type="revolute">
    <origin xyz="-0.0178895 -0.145625 0" rpy="0 0 0"/>
    <axis xyz="-1.0 0.0 0.0"/>
    <parent link="r_thigh"/>
    <child link="r_shank"/>
    <limit effort="50000" lower="-1.74532925199" upper="0.0" velocity="50000"/>
    <dynamics damping="0.223"/>
  </joint>
  <link name="SCSYS_EMS_ACCEL1"/>
  <joint name="SCSYS_EMS_ACCEL1_fixed_joint" type="fixed">
    <origin xyz="0.0279291 -0.092765 0.04351373" rpy="0 -0.218166543341 1.57079632679"/>
    <parent link="r_shank"/>
    <child link="SCSYS_EMS_ACCEL1"/>
    <dynamics damping="0.1"/>
  </joint>
  <link name="SCSYS_EMS_GYRO1"/>
  <joint name="SCSYS_EMS_GYRO1_fixed_joint" type="fixed">
    <origin xyz="0.028433 -0.088301 0.044503292" rpy="0 -0.218166543341 1.57079632679"/>
    <parent link="r_shank"/>
    <child link="SCSYS_EMS_GYRO1"/>
    <dynamics damping="0.1"/>
  </joint>
  <link name="SCSYS_MTB_ACCEL0"/>
  <joint name="SCSYS_MTB_ACCEL0_fixed_joint" type="fixed">
    <origin xyz="0.0278886 -0.010933 0.0544518" rpy="-0.349065638037 3.9709492862e-05 -1.57068722577"/>
    <parent link="r_shank"/>
    <child link="SCSYS_MTB_ACCEL0"/>
    <dynamics damping="0.1"/>
  </joint>
  <link name="SCSYS_MTB_ACCEL_10"/>
  <joint name="SCSYS_MTB_ACCEL_10_fixed_joint" type="fixed">
    <origin xyz="-0.0030927 -0.010933 0.05313395" rpy="0.244346164411 -2.808784262e-05 -1.57068367232"/>
    <parent link="r_shank"/>
    <child link="SCSYS_MTB_ACCEL_10"/>
    <dynamics damping="0.1"/>
  </joint>
  <link name="SCSYS_MTB_ACCEL_20"/>
  <joint name="SCSYS_MTB_ACCEL_20_fixed_joint" type="fixed">
    <origin xyz="-0.0286545 -0.050082 0.0259155" rpy="1.30899714456 -0.000143911236881 -1.57075776595"/>
    <parent link="r_shank"/>
    <child link="SCSYS_MTB_ACCEL_20"/>
    <dynamics damping="0.1"/>
  </joint>
  <link name="SCSYS_MTB_ACCEL_30"/>
  <joint name="SCSYS_MTB_ACCEL_30_fixed_joint" type="fixed">
    <origin xyz="0.0558086 -0.099573 0.0184576" rpy="-1.30899714532 0.000112146780783 -1.57076627686"/>
    <parent link="r_shank"/>
    <child link="SCSYS_MTB_ACCEL_30"/>
    <dynamics damping="0.1"/>
  </joint>
  <link name="r_ankle">
    <inertial>
      <origin xyz="0.0265327 7.4e-05 0.0150166" rpy="0 0 0"/>
      <mass value="0.554181"/>
      <inertia ixx="0.000368295" ixy="2.92938e-07" ixz="-1.37313e-05" iyy="0.000414394" iyz="1.75709e-06" izz="0.00028171"/>
    </inertial>
    <visual>
      <origin xyz="0.09712 0.587138 0.0437089998094" rpy="0 0 0"/>
      <geometry>
        <mesh filename="model://iCubHeidelberg01_model/dae_meshes/sim_sea_r_ankle_prt.dae" scale="0.001 0.001 0.001"/>
      </geometry>
      <material name="cyan">
        <color rgba="0 1 1 1"/>
      </material>
    </visual>
    <collision>
      <origin xyz="0.09712 0.587138 0.0437089998094" rpy="0 0 0"/>
      <geometry>
        <mesh filename="model://iCubHeidelberg01_model/dae_meshes/sim_sea_r_ankle_prt.dae" scale="0.001 0.001 0.001"/>
      </geometry>
    </collision>
  </link>
  <joint name="r_ankle_pitch" type="revolute">
    <origin xyz="-0.0129305 -0.2005 0" rpy="0 0 0"/>
    <axis xyz="1.0 0.0 0.0"/>
    <parent link="r_shank"/>
    <child link="r_ankle"/>
    <limit effort="50000" lower="-0.349065850399" upper="0.523598775598" velocity="50000"/>
    <dynamics damping="0.223"/>
  </joint>
  <link name="r_upper_foot">
    <inertial>
      <origin xyz="2.1e-06 -0.03381 -0.044405867" rpy="0 0 0"/>
      <mass value="0.224797"/>
      <inertia ixx="0.000317712" ixy="0.0" ixz="9.41219e-09" iyy="0.000243566" iyz="1.32865e-05" izz="0.000132578"/>
    </inertial>
    <visual>
      <origin xyz="0.0701 0.587138 -0.000853467381356" rpy="0 0 0"/>
      <geometry>
        <mesh filename="model://iCubHeidelberg01_model/dae_meshes/sim_sea_r_foot_prt.dae" scale="0.001 0.001 0.001"/>
      </geometry>
      <material name="green"/>
    </visual>
    <collision>
      <origin xyz="0.0701 0.587138 -0.000853467381356" rpy="0 0 0"/>
      <geometry>
        <mesh filename="model://iCubHeidelberg01_model/dae_meshes/sim_sea_r_foot_prt.dae" scale="0.001 0.001 0.001"/>
      </geometry>
    </collision>
  </link>
  <joint name="r_ankle_roll" type="revolute">
    <origin xyz="0.02702 0 0.044562467" rpy="0 0 0"/>
    <axis xyz="-0.0 -0.0 -1.0"/>
    <parent link="r_ankle"/>
    <child link="r_upper_foot"/>
    <limit effort="50000" lower="-0.349065850399" upper="0.349065850399" velocity="50000"/>
    <dynamics damping="0.223"/>
  </joint>
  <link name="r_foot">
    <inertial>
      <origin xyz="-0.0752084 -0.648957 -0.0103374996186" rpy="0 0 0"/>
      <mass value="0.907917"/>
      <inertia ixx="0.00297466" ixy="8.70649e-07" ixz="-0.000138843" iyy="0.00344276" iyz="-1.76747e-05" izz="0.000681043"/>
    </inertial>
    <visual>
      <origin xyz="0 0 0" rpy="0 0 0"/>
      <geometry>
        <mesh filename="model://iCubHeidelberg01_model/dae_meshes/sim_sea_r_sole_prt.dae" scale="0.001 0.001 0.001"/>
      </geometry>
      <material name="white">
        <color rgba="1 1 1 1"/>
      </material>
    </visual>
    <collision>
      <origin xyz="0 0 0" rpy="0 0 0"/>
      <geometry>
        <mesh filename="model://iCubHeidelberg01_model/dae_meshes/sim_sea_r_sole_prt.dae" scale="0.001 0.001 0.001"/>
      </geometry>
    </collision>
  </link>
  <joint name="r_foot_ft_sensor" type="fixed">
    <origin xyz="0.0701 0.587138 -0.000853467381377" rpy="0 0 0"/>
    <parent link="r_upper_foot"/>
    <child link="r_foot"/>
    <dynamics damping="0.1"/>
  </joint>
  <link name="SCSYS_MTB_ACCEL1"/>
  <joint name="SCSYS_MTB_ACCEL1_fixed_joint" type="fixed">
    <origin xyz="-0.069293 -0.646223 0.0562654003814" rpy="1.57079632679 0 0"/>
    <parent link="r_foot"/>
    <child link="SCSYS_MTB_ACCEL1"/>
    <dynamics damping="0.1"/>
  </joint>
  <link name="SCSYS_MTB_ACCEL_11"/>
  <joint name="SCSYS_MTB_ACCEL_11_fixed_joint" type="fixed">
    <origin xyz="-0.0582928 -0.646223 0.0312654003814" rpy="1.57079632679 0 0"/>
    <parent link="r_foot"/>
    <child link="SCSYS_MTB_ACCEL_11"/>
    <dynamics damping="0.1"/>
  </joint>
  <link name="l_hip_1">
    <inertial>
      <origin xyz="-0.086666 -2.60000000002e-05 0.0002121" rpy="0 0 0"/>
      <mass value="0.610394"/>
      <inertia ixx="0.000304601" ixy="7.97583e-07" ixz="-2.29911e-07" iyy="0.000454222" iyz="1.14938e-06" izz="0.000453573"/>
    </inertial>
    <visual>
      <origin xyz="-0.026 0.151913 -0.0428515" rpy="0 0 0"/>
      <geometry>
        <mesh filename="model://iCubHeidelberg01_model/dae_meshes/sim_sea_l_hip_1_prt.dae" scale="0.001 0.001 0.001"/>
      </geometry>
      <material name="dblue">
        <color rgba="0 0 0.8 1"/>
      </material>
    </visual>
    <collision>
      <origin xyz="-0.026 0.151913 -0.0428515" rpy="0 0 0"/>
      <geometry>
        <mesh filename="model://iCubHeidelberg01_model/dae_meshes/sim_sea_l_hip_1_prt.dae" scale="0.001 0.001 0.001"/>
      </geometry>
    </collision>
  </link>
  <joint name="l_hip_pitch" type="revolute">
    <origin xyz="-0.026 -0.151913 -0.0428515" rpy="3.14159265359 0 3.14159265359"/>
    <axis xyz="1.0 0.0 0.0"/>
    <parent link="root_link"/>
    <child link="l_hip_1"/>
    <limit effort="50000" lower="-0.523598775598" upper="1.4835298642" velocity="50000"/>
    <dynamics damping="0.223"/>
  </joint>
  <link name="l_hip_2">
    <inertial>
      <origin xyz="-1.5e-06 -0.03665 -0.0231604" rpy="0 0 0"/>
      <mass value="0.292811"/>
      <inertia ixx="0.000410194" ixy="1.58042e-08" ixz="6.95352e-09" iyy="0.000232087" iyz="2.60468e-05" izz="0.000252169"/>
    </inertial>
    <visual>
      <origin xyz="0.0701 0.151913 -0.0690985998093" rpy="0 0 0"/>
      <geometry>
        <mesh filename="model://iCubHeidelberg01_model/dae_meshes/sim_sea_l_hip_2_prt.dae" scale="0.001 0.001 0.001"/>
      </geometry>
      <material name="dgreen">
        <color rgba="0.1 0.8 0.1 1"/>
      </material>
    </visual>
    <collision>
      <origin xyz="0.0701 0.151913 -0.0690985998093" rpy="0 0 0"/>
      <geometry>
        <mesh filename="model://iCubHeidelberg01_model/dae_meshes/sim_sea_l_hip_2_prt.dae" scale="0.001 0.001 0.001"/>
      </geometry>
    </collision>
  </link>
  <joint name="l_hip_roll" type="revolute">
    <origin xyz="-0.0961 0 0.0262471" rpy="0 0 0"/>
    <axis xyz="-0.0 1.26404e-12 -1.0"/>
    <parent link="l_hip_1"/>
    <child link="l_hip_2"/>
    <limit effort="50000" lower="0.0" upper="1.57079632679" velocity="50000"/>
    <dynamics damping="0.223"/>
  </joint>
  <link name="l_upper_thigh">
    <inertial>
      <origin xyz="-0.0699184 -0.234474 0.0438122998092" rpy="0 0 0"/>
      <mass value="0.122687"/>
      <inertia ixx="3.09316e-05" ixy="2.08202e-07" ixz="-1.99589e-08" iyy="5.53314e-05" iyz="9.22295e-09" izz="3.08107e-05"/>
    </inertial>
    <visual>
      <origin xyz="0 0 0" rpy="0 0 0"/>
      <geometry>
        <mesh filename="model://iCubHeidelberg01_model/dae_meshes/sim_sea_l_upper_thigh_prt.dae" scale="0.001 0.001 0.001"/>
      </geometry>
      <material name="gray">
        <color rgba="0.5 0.5 0.5 1"/>
      </material>
    </visual>
    <collision>
      <origin xyz="0 0 0" rpy="0 0 0"/>
      <geometry>
        <mesh filename="model://iCubHeidelberg01_model/dae_meshes/sim_sea_l_upper_thigh_prt.dae" scale="0.001 0.001 0.001"/>
      </geometry>
    </collision>
  </link>
  <joint name="l_leg_ft_sensor" type="fixed">
    <origin xyz="0.0701 0.151913 -0.0690985998093" rpy="0 0 0"/>
    <parent link="l_hip_2"/>
    <child link="l_upper_thigh"/>
    <dynamics damping="0.1"/>
  </joint>
  <link name="l_thigh">
    <inertial>
      <origin xyz="-0.0001448 -0.065088 -0.00910780000008" rpy="0 0 0"/>
      <mass value="2.82909"/>
      <inertia ixx="0.00961828" ixy="0.000277522" ixz="7.45373e-06" iyy="0.00385108" iyz="-0.000180645" izz="0.00968964"/>
    </inertial>
    <visual>
      <origin xyz="0.0701 0.241013 -0.0437089998092" rpy="0 0 0"/>
      <geometry>
        <mesh filename="model://iCubHeidelberg01_model/dae_meshes/sim_sea_l_thigh_prt.dae" scale="0.001 0.001 0.001"/>
      </geometry>
      <material name="green"/>
    </visual>
    <collision>
      <origin xyz="0.0701 0.241013 -0.0437089998092" rpy="0 0 0"/>
      <geometry>
        <mesh filename="model://iCubHeidelberg01_model/dae_meshes/sim_sea_l_thigh_prt.dae" scale="0.001 0.001 0.001"/>
      </geometry>
    </collision>
  </link>
  <joint name="l_hip_yaw" type="revolute">
    <origin xyz="-0.0701 -0.244213 0.0437089998092" rpy="0 0 0"/>
    <axis xyz="-0.0 1.0 1.22451e-12"/>
    <parent link="l_upper_thigh"/>
    <child link="l_thigh"/>
    <limit effort="50000" lower="-1.2217304764" upper="1.2217304764" velocity="50000"/>
    <dynamics damping="0.223"/>
  </joint>
  <link name="SCSYS_EMS_ACCEL2"/>
  <joint name="SCSYS_EMS_ACCEL2_fixed_joint" type="fixed">
    <origin xyz="0.0404072 -0.040027 0.0125751" rpy="-1.57079632679 0 1.57079632679"/>
    <parent link="l_thigh"/>
    <child link="SCSYS_EMS_ACCEL2"/>
    <dynamics damping="0.1"/>
  </joint>
  <link name="SCSYS_EMS_GYRO2"/>
  <joint name="SCSYS_EMS_GYRO2_fixed_joint" type="fixed">
    <origin xyz="0.0404072 -0.035455 0.013079" rpy="-1.57079632679 0 1.57079632679"/>
    <parent link="l_thigh"/>
    <child link="SCSYS_EMS_GYRO2"/>
    <dynamics damping="0.1"/>
  </joint>
  <link name="SCSYS_EMS_ACCEL_11"/>
  <joint name="SCSYS_EMS_ACCEL_11_fixed_joint" type="fixed">
    <origin xyz="-0.040407 -0.083207 0.0125770999999" rpy="-1.57079632679 0 -1.57079632679"/>
    <parent link="l_thigh"/>
    <child link="SCSYS_EMS_ACCEL_11"/>
    <dynamics damping="0.1"/>
  </joint>
  <link name="SCSYS_EMS_GYRO_11"/>
  <joint name="SCSYS_EMS_GYRO_11_fixed_joint" type="fixed">
    <origin xyz="-0.040407 -0.087779 0.0130809999999" rpy="-1.57079632679 0 -1.57079632679"/>
    <parent link="l_thigh"/>
    <child link="SCSYS_EMS_GYRO_11"/>
    <dynamics damping="0.1"/>
  </joint>
  <link name="SCSYS_MTB_ACCEL2"/>
  <joint name="SCSYS_MTB_ACCEL2_fixed_joint" type="fixed">
    <origin xyz="0.0414996 -0.011459 -0.03416985" rpy="1.18682376736 -0.000365167546644 -1.57082213412"/>
    <parent link="l_thigh"/>
    <child link="SCSYS_MTB_ACCEL2"/>
    <dynamics damping="0.1"/>
  </joint>
  <link name="SCSYS_MTB_ACCEL_12"/>
  <joint name="SCSYS_MTB_ACCEL_12_fixed_joint" type="fixed">
    <origin xyz="0.0162386 -0.0263660000001 0.0437518" rpy="-3.14159260377 -0.000429089989188 -1.57091243007"/>
    <parent link="l_thigh"/>
    <child link="SCSYS_MTB_ACCEL_12"/>
    <dynamics damping="0.1"/>
  </joint>
  <link name="SCSYS_MTB_ACCEL_21"/>
  <joint name="SCSYS_MTB_ACCEL_21_fixed_joint" type="fixed">
    <origin xyz="-0.0157594 -0.0263650000001 0.0437518" rpy="3.14159265359 -0.0004290899922 -1.57079632679"/>
    <parent link="l_thigh"/>
    <child link="SCSYS_MTB_ACCEL_21"/>
    <dynamics damping="0.1"/>
  </joint>
  <link name="SCSYS_MTB_ACCEL_31"/>
  <joint name="SCSYS_MTB_ACCEL_31_fixed_joint" type="fixed">
    <origin xyz="-0.049485 -0.064411 -0.0117282000001" rpy="-1.57079632679 -0.000312931025653 -1.57079632679"/>
    <parent link="l_thigh"/>
    <child link="SCSYS_MTB_ACCEL_31"/>
    <dynamics damping="0.1"/>
  </joint>
  <link name="SCSYS_MTB_ACCEL_40"/>
  <joint name="SCSYS_MTB_ACCEL_40_fixed_joint" type="fixed">
    <origin xyz="-0.031565 0.0425260000001 -0.0420643799999" rpy="-0.837758053858 -0.000342790748128 -1.57071863707"/>
    <parent link="l_thigh"/>
    <child link="SCSYS_MTB_ACCEL_40"/>
    <dynamics damping="0.1"/>
  </joint>
  <link name="SCSYS_MTB_ACCEL_50"/>
  <joint name="SCSYS_MTB_ACCEL_50_fixed_joint" type="fixed">
    <origin xyz="-0.0083839 0.0326420000001 -0.05341396" rpy="-0.26179934248 -0.000399026343764 -1.5706841771"/>
    <parent link="l_thigh"/>
    <child link="SCSYS_MTB_ACCEL_50"/>
    <dynamics damping="0.1"/>
  </joint>
  <link name="SCSYS_MTB_ACCEL_60"/>
  <joint name="SCSYS_MTB_ACCEL_60_fixed_joint" type="fixed">
    <origin xyz="-0.0150686 -0.00242899999993 -0.0538284" rpy="0 -0.000429089989188 -1.57068022352"/>
    <parent link="l_thigh"/>
    <child link="SCSYS_MTB_ACCEL_60"/>
    <dynamics damping="0.1"/>
  </joint>
  <link name="SCSYS_MTB_ACCEL_70"/>
  <joint name="SCSYS_MTB_ACCEL_70_fixed_joint" type="fixed">
    <origin xyz="0.0144314 -0.00242899999993 -0.0538284" rpy="0 -0.000429089989188 -1.57068022352"/>
    <parent link="l_thigh"/>
    <child link="SCSYS_MTB_ACCEL_70"/>
    <dynamics damping="0.1"/>
  </joint>
  <link name="l_shank">
    <inertial>
      <origin xyz="0.0120744 -0.083027 -0.0073589000001" rpy="0 0 0"/>
      <mass value="3.31111"/>
      <inertia ixx="0.0108069" ixy="0.000604622" ixz="5.98023e-06" iyy="0.00495004" iyz="-0.000693558" izz="0.0116311"/>
    </inertial>
    <visual>
      <origin xyz="0.0841895 0.386638 -0.043708999809" rpy="0 0 0"/>
      <geometry>
        <mesh filename="model://iCubHeidelberg01_model/dae_meshes/sim_sea_l_shank_prt.dae" scale="0.001 0.001 0.001"/>
      </geometry>
      <material name="black"/>
    </visual>
    <collision>
      <origin xyz="0.0841895 0.386638 -0.043708999809" rpy="0 0 0"/>
      <geometry>
        <mesh filename="model://iCubHeidelberg01_model/dae_meshes/sim_sea_l_shank_prt.dae" scale="0.001 0.001 0.001"/>
      </geometry>
    </collision>
  </link>
  <joint name="l_knee" type="revolute">
    <origin xyz="-0.0178895 -0.145625 0" rpy="0 0 0"/>
    <axis xyz="1.0 0.0 0.0"/>
    <parent link="l_thigh"/>
    <child link="l_shank"/>
    <limit effort="50000" lower="-1.74532925199" upper="0.0" velocity="50000"/>
    <dynamics damping="0.223"/>
  </joint>
  <link name="SCSYS_EMS_ACCEL3"/>
  <joint name="SCSYS_EMS_ACCEL3_fixed_joint" type="fixed">
    <origin xyz="0.0279291 -0.0927649999999 -0.0435137300001" rpy="0 0.21816654334 1.57079632679"/>
    <parent link="l_shank"/>
    <child link="SCSYS_EMS_ACCEL3"/>
    <dynamics damping="0.1"/>
  </joint>
  <link name="SCSYS_EMS_GYRO3"/>
  <joint name="SCSYS_EMS_GYRO3_fixed_joint" type="fixed">
    <origin xyz="0.028433 -0.0883009999999 -0.0445032920001" rpy="0 0.21816654334 1.57079632679"/>
    <parent link="l_shank"/>
    <child link="SCSYS_EMS_GYRO3"/>
    <dynamics damping="0.1"/>
  </joint>
  <link name="SCSYS_MTB_ACCEL3"/>
  <joint name="SCSYS_MTB_ACCEL3_fixed_joint" type="fixed">
    <origin xyz="0.0278886 -0.0109329999999 -0.0544518" rpy="0.349065638036 -3.97094922217e-05 -1.57068722577"/>
    <parent link="l_shank"/>
    <child link="SCSYS_MTB_ACCEL3"/>
    <dynamics damping="0.1"/>
  </joint>
  <link name="SCSYS_MTB_ACCEL_13"/>
  <joint name="SCSYS_MTB_ACCEL_13_fixed_joint" type="fixed">
    <origin xyz="-0.0030927 -0.0109329999999 -0.05313395" rpy="-0.244346164411 2.80878432373e-05 -1.57068367232"/>
    <parent link="l_shank"/>
    <child link="SCSYS_MTB_ACCEL_13"/>
    <dynamics damping="0.1"/>
  </joint>
  <link name="SCSYS_MTB_ACCEL_22"/>
  <joint name="SCSYS_MTB_ACCEL_22_fixed_joint" type="fixed">
    <origin xyz="-0.0286545 -0.050082 -0.0259155000001" rpy="-1.30899714456 0.000143911238098 -1.57075776595"/>
    <parent link="l_shank"/>
    <child link="SCSYS_MTB_ACCEL_22"/>
    <dynamics damping="0.1"/>
  </joint>
  <link name="SCSYS_MTB_ACCEL_32"/>
  <joint name="SCSYS_MTB_ACCEL_32_fixed_joint" type="fixed">
    <origin xyz="0.0558086 -0.099573 -0.0184576000001" rpy="1.30899714532 -0.000112146779566 -1.57076627686"/>
    <parent link="l_shank"/>
    <child link="SCSYS_MTB_ACCEL_32"/>
    <dynamics damping="0.1"/>
  </joint>
  <link name="l_ankle">
    <inertial>
      <origin xyz="0.0265327 7.40000000186e-05 -0.0150166" rpy="0 0 0"/>
      <mass value="0.554181"/>
      <inertia ixx="0.000368295" ixy="2.92938e-07" ixz="-1.37313e-05" iyy="0.000414394" iyz="1.75709e-06" izz="0.00028171"/>
    </inertial>
    <visual>
      <origin xyz="0.09712 0.587138 -0.0437089998087" rpy="0 0 0"/>
      <geometry>
        <mesh filename="model://iCubHeidelberg01_model/dae_meshes/sim_sea_l_ankle_prt.dae" scale="0.001 0.001 0.001"/>
      </geometry>
      <material name="red"/>
    </visual>
    <collision>
      <origin xyz="0.09712 0.587138 -0.0437089998087" rpy="0 0 0"/>
      <geometry>
        <mesh filename="model://iCubHeidelberg01_model/dae_meshes/sim_sea_l_ankle_prt.dae" scale="0.001 0.001 0.001"/>
      </geometry>
    </collision>
  </link>
  <joint name="l_ankle_pitch" type="revolute">
    <origin xyz="-0.0129305 -0.2005 0" rpy="0 0 0"/>
    <axis xyz="-1.0 0.0 0.0"/>
    <parent link="l_shank"/>
    <child link="l_ankle"/>
    <limit effort="50000" lower="-0.349065850399" upper="0.523598775598" velocity="50000"/>
    <dynamics damping="0.223"/>
  </joint>
  <link name="l_upper_foot">
    <inertial>
      <origin xyz="2.1e-06 -0.0338100000001 0.044405867" rpy="0 0 0"/>
      <mass value="0.224797"/>
      <inertia ixx="0.000317712" ixy="0.0" ixz="9.41219e-09" iyy="0.000243566" iyz="1.32865e-05" izz="0.000132578"/>
    </inertial>
    <visual>
      <origin xyz="0.0701 0.587138 0.000853467382004" rpy="0 0 0"/>
      <geometry>
        <mesh filename="model://iCubHeidelberg01_model/dae_meshes/sim_sea_l_foot_prt.dae" scale="0.001 0.001 0.001"/>
      </geometry>
      <material name="blue"/>
    </visual>
    <collision>
      <origin xyz="0.0701 0.587138 0.000853467382004" rpy="0 0 0"/>
      <geometry>
        <mesh filename="model://iCubHeidelberg01_model/dae_meshes/sim_sea_l_foot_prt.dae" scale="0.001 0.001 0.001"/>
      </geometry>
    </collision>
  </link>
  <joint name="l_ankle_roll" type="revolute">
    <origin xyz="0.02702 0 -0.044562467" rpy="0 0 0"/>
    <axis xyz="-0.0 1.23785e-12 -1.0"/>
    <parent link="l_ankle"/>
    <child link="l_upper_foot"/>
    <limit effort="50000" lower="-0.349065850399" upper="0.349065850399" velocity="50000"/>
    <dynamics damping="0.223"/>
  </joint>
  <link name="l_foot">
    <inertial>
      <origin xyz="-0.0752084 -0.648957 0.0103374996179" rpy="0 0 0"/>
      <mass value="0.907917"/>
      <inertia ixx="0.00297466" ixy="8.70649e-07" ixz="-0.000138843" iyy="0.00344276" iyz="-1.76747e-05" izz="0.000681043"/>
    </inertial>
    <visual>
      <origin xyz="0 0 0" rpy="0 0 0"/>
      <geometry>
        <mesh filename="model://iCubHeidelberg01_model/dae_meshes/sim_sea_l_sole_prt.dae" scale="0.001 0.001 0.001"/>
      </geometry>
      <material name="yellow"/>
    </visual>
    <collision>
      <origin xyz="0 0 0" rpy="0 0 0"/>
      <geometry>
        <mesh filename="model://iCubHeidelberg01_model/dae_meshes/sim_sea_l_sole_prt.dae" scale="0.001 0.001 0.001"/>
      </geometry>
    </collision>
  </link>
  <joint name="l_foot_ft_sensor" type="fixed">
    <origin xyz="0.0701 0.587138 0.000853467382024" rpy="0 0 0"/>
    <parent link="l_upper_foot"/>
    <child link="l_foot"/>
    <dynamics damping="0.1"/>
  </joint>
  <link name="SCSYS_MTB_ACCEL4"/>
  <joint name="SCSYS_MTB_ACCEL4_fixed_joint" type="fixed">
    <origin xyz="-0.069293 -0.646223 -0.0562654003821" rpy="-1.57079632679 0 0"/>
    <parent link="l_foot"/>
    <child link="SCSYS_MTB_ACCEL4"/>
    <dynamics damping="0.1"/>
  </joint>
  <link name="SCSYS_MTB_ACCEL_14"/>
  <joint name="SCSYS_MTB_ACCEL_14_fixed_joint" type="fixed">
    <origin xyz="-0.0582928 -0.646223 -0.0312654003821" rpy="-1.57079632679 0 0"/>
    <parent link="l_foot"/>
    <child link="SCSYS_MTB_ACCEL_14"/>
    <dynamics damping="0.1"/>
  </joint>
  <link name="lap_belt_1">
    <inertial>
      <origin xyz="0.039241235 0.0281103000005 -0.00332089999546" rpy="0 0 0"/>
      <mass value="0.479404"/>
      <inertia ixx="0.000332949" ixy="-2.39782e-06" ixz="3.60866e-07" iyy="0.000309732" iyz="1.13592e-05" izz="0.000223739"/>
    </inertial>
    <visual>
      <origin xyz="0.0393999998093 0.032 0.0364" rpy="0 0 0"/>
      <geometry>
        <mesh filename="model://iCubHeidelberg01_model/dae_meshes/sim_sea_lap_belt_1_prt.dae" scale="0.001 0.001 0.001"/>
      </geometry>
      <material name="pink"/>
    </visual>
    <collision>
      <origin xyz="0.0393999998093 0.032 0.0364" rpy="0 0 0"/>
      <geometry>
        <mesh filename="model://iCubHeidelberg01_model/dae_meshes/sim_sea_lap_belt_1_prt.dae" scale="0.001 0.001 0.001"/>
      </geometry>
    </collision>
  </link>
  <joint name="torso_pitch" type="revolute">
    <origin xyz="-0.0394 -0.032 -0.0364" rpy="0 0 0"/>
    <axis xyz="1.0 0.0 0.0"/>
    <parent link="root_link"/>
    <child link="lap_belt_1"/>
    <limit effort="50000" lower="-0.349065850399" upper="1.2217304764" velocity="50000"/>
    <dynamics damping="0.06"/>
  </joint>
  <link name="lap_belt_2">
    <inertial>
      <origin xyz="-0.000107779809265 0.0247916000001 0.053524900004" rpy="0 0 0"/>
      <mass value="0.327897"/>
      <inertia ixx="0.000531991" ixy="5.54439e-07" ixz="-2.83073e-07" iyy="0.00042219" iyz="2.9326e-05" izz="0.000303736"/>
    </inertial>
    <visual>
      <origin xyz="0 0 0.0902389999948" rpy="0 0 0"/>
      <geometry>
        <mesh filename="model://iCubHeidelberg01_model/dae_meshes/sim_kor_lap_belt_2_prt.dae" scale="0.001 0.001 0.001"/>
      </geometry>
      <material name="cyan"/>
    </visual>
    <collision>
      <origin xyz="0 0 0.0902389999948" rpy="0 0 0"/>
      <geometry>
        <mesh filename="model://iCubHeidelberg01_model/dae_meshes/sim_kor_lap_belt_2_prt.dae" scale="0.001 0.001 0.001"/>
      </geometry>
    </collision>
  </link>
  <joint name="torso_roll" type="revolute">
    <origin xyz="0.0393999998093 0.032 -0.0538389999948" rpy="0 0 0"/>
    <axis xyz="0.0 -1.61681e-10 -1.0"/>
    <parent link="lap_belt_1"/>
    <child link="lap_belt_2"/>
    <limit effort="50000" lower="-0.523598775598" upper="0.523598775598" velocity="50000"/>
    <dynamics damping="0.06"/>
  </joint>
  <link name="chest">
    <inertial>
      <origin xyz="-0.000635442809265 0.094882000002 -0.0123862999847" rpy="0 0 0"/>
      <mass value="9.71648"/>
      <inertia ixx="0.0489161" ixy="-6.26711e-05" ixz="-0.000115394" iyy="0.0629082" iyz="0.00259595" izz="0.0626678"/>
    </inertial>
    <visual>
      <origin xyz="0 -0.0519999999991 0.0308999999864" rpy="0 0 0"/>
      <geometry>
        <mesh filename="model://iCubHeidelberg01_model/dae_meshes/sim_kor_chest_prt.dae" scale="0.001 0.001 0.001"/>
      </geometry>
      <material name="green"/>
    </visual>
    <collision>
      <origin xyz="0 -0.0519999999991 0.0308999999864" rpy="0 0 0"/>
      <geometry>
        <mesh filename="model://iCubHeidelberg01_model/dae_meshes/sim_kor_chest_prt.dae" scale="0.001 0.001 0.001"/>
      </geometry>
    </collision>
  </link>
  <joint name="torso_yaw" type="revolute">
    <origin xyz="0 0.0519999999991 0.0593390000084" rpy="0 0 0"/>
    <axis xyz="0.0 -1.0 1.61681e-10"/>
    <parent link="lap_belt_2"/>
    <child link="chest"/>
    <limit effort="50000" lower="-0.872664625997" upper="0.872664625997" velocity="50000"/>
    <dynamics damping="0.06"/>
  </joint>
  <link name="imu_frame"/>
  <joint name="imu_frame_fixed_joint" type="fixed">
    <origin xyz="-0.0169999998093 0.100500000006 -0.0380999999838" rpy="3.14159265359 0 0"/>
    <parent link="chest"/>
    <child link="imu_frame"/>
    <dynamics damping="0.1"/>
  </joint>
  <link name="SCSYS_MTX_ACCEL_0"/>
  <joint name="SCSYS_MTX_ACCEL_0_fixed_joint" type="fixed">
    <origin xyz="-0.0169999998093 0.100500000006 -0.0380999999838" rpy="3.14159265359 0 0"/>
    <parent link="chest"/>
    <child link="SCSYS_MTX_ACCEL_0"/>
    <dynamics damping="0.1"/>
  </joint>
  <link name="WEIGHT-1KG-4">
    <inertial>
      <origin xyz="-1e-06 1.46e-05 -1e-06" rpy="0 0 0"/>
      <mass value="1.00161"/>
      <inertia ixx="0.0010891" ixy="3.14425e-08" ixz="0.0" iyy="0.00108866" iyz="4.73842e-08" izz="0.00213553"/>
    </inertial>
    <visual>
      <origin xyz="0 0 0" rpy="0 0 0"/>
      <geometry>
        <mesh filename="model://iCubHeidelberg01_model/dae_meshes/weight-1kg_prt.dae" scale="0.001 0.001 0.001"/>
      </geometry>
      <material name="WEIGHT-1KG-4_color">
        <color rgba="0.666667 0.666667 0.666667 1.0"/>
      </material>
    </visual>
    <collision>
      <origin xyz="0 0 0" rpy="0 0 0"/>
      <geometry>
        <mesh filename="model://iCubHeidelberg01_model/dae_meshes/weight-1kg_prt.dae" scale="0.001 0.001 0.001"/>
      </geometry>
    </collision>
  </link>
  <joint name="chest_weight_5" type="fixed">
    <origin xyz="-0.132249999809 0.0955 0" rpy="1.57079632679 0 1.57079632679"/>
    <parent link="chest"/>
    <child link="WEIGHT-1KG-4"/>
    <dynamics damping="0.1"/>
  </joint>
  <link name="WEIGHT-1KG-3">
    <inertial>
      <origin xyz="-1.137569265e-06 1.46000000002e-05 -9.99999997586e-07" rpy="0 0 0"/>
      <mass value="1.00161"/>
      <inertia ixx="0.0010891" ixy="3.14425e-08" ixz="0.0" iyy="0.00108866" iyz="4.73842e-08" izz="0.00213553"/>
    </inertial>
    <visual>
      <origin xyz="0 0 0" rpy="0 0 0"/>
      <geometry>
        <mesh filename="model://iCubHeidelberg01_model/dae_meshes/weight-1kg_prt.dae" scale="0.001 0.001 0.001"/>
      </geometry>
      <material name="WEIGHT-1KG-3_color">
        <color rgba="0.666667 0.666667 0.666667 1.0"/>
      </material>
    </visual>
    <collision>
      <origin xyz="0 0 0" rpy="0 0 0"/>
      <geometry>
        <mesh filename="model://iCubHeidelberg01_model/dae_meshes/weight-1kg_prt.dae" scale="0.001 0.001 0.001"/>
      </geometry>
    </collision>
  </link>
  <joint name="chest_weight_4" type="fixed">
    <origin xyz="0 0.22525 0" rpy="1.57079632679 0 0"/>
    <parent link="chest"/>
    <child link="WEIGHT-1KG-3"/>
    <dynamics damping="0.1"/>
  </joint>
  <link name="WEIGHT-1KG-5">
    <inertial>
      <origin xyz="-1e-06 1.46e-05 -1e-06" rpy="0 0 0"/>
      <mass value="1.00161"/>
      <inertia ixx="0.0010891" ixy="3.14425e-08" ixz="0.0" iyy="0.00108866" iyz="4.73842e-08" izz="0.00213553"/>
    </inertial>
    <visual>
      <origin xyz="0 0 0" rpy="0 0 0"/>
      <geometry>
        <mesh filename="model://iCubHeidelberg01_model/dae_meshes/weight-1kg_prt.dae" scale="0.001 0.001 0.001"/>
      </geometry>
      <material name="WEIGHT-1KG-5_color">
        <color rgba="0.666667 0.666667 0.666667 1.0"/>
      </material>
    </visual>
    <collision>
      <origin xyz="0 0 0" rpy="0 0 0"/>
      <geometry>
        <mesh filename="model://iCubHeidelberg01_model/dae_meshes/weight-1kg_prt.dae" scale="0.001 0.001 0.001"/>
      </geometry>
    </collision>
  </link>
  <joint name="chest_weight_6" type="fixed">
    <origin xyz="-0.150749999809 0.0955 0" rpy="1.57079632679 0 1.57079632679"/>
    <parent link="chest"/>
    <child link="WEIGHT-1KG-5"/>
    <dynamics damping="0.1"/>
  </joint>
  <link name="WEIGHT-1KG">
    <inertial>
      <origin xyz="-1.00000000003e-06 1.46e-05 -1e-06" rpy="0 0 0"/>
      <mass value="1.00161"/>
      <inertia ixx="0.0010891" ixy="3.14425e-08" ixz="0.0" iyy="0.00108866" iyz="4.73842e-08" izz="0.00213553"/>
    </inertial>
    <visual>
      <origin xyz="0 0 0" rpy="0 0 0"/>
      <geometry>
        <mesh filename="model://iCubHeidelberg01_model/dae_meshes/weight-1kg_prt.dae" scale="0.001 0.001 0.001"/>
      </geometry>
      <material name="WEIGHT-1KG_color">
        <color rgba="0.666667 0.666667 0.666667 1.0"/>
      </material>
    </visual>
    <collision>
      <origin xyz="0 0 0" rpy="0 0 0"/>
      <geometry>
        <mesh filename="model://iCubHeidelberg01_model/dae_meshes/weight-1kg_prt.dae" scale="0.001 0.001 0.001"/>
      </geometry>
    </collision>
  </link>
  <joint name="chest_weight_1" type="fixed">
    <origin xyz="0.132250000191 0.0955 0" rpy="1.57079632679 0 -1.57079632679"/>
    <parent link="chest"/>
    <child link="WEIGHT-1KG"/>
    <dynamics damping="0.1"/>
  </joint>
  <link name="WEIGHT-1KG-2">
    <inertial>
      <origin xyz="-1.137569265e-06 1.46000000002e-05 -9.99999997642e-07" rpy="0 0 0"/>
      <mass value="1.00161"/>
      <inertia ixx="0.0010891" ixy="3.14425e-08" ixz="0.0" iyy="0.00108866" iyz="4.73842e-08" izz="0.00213553"/>
    </inertial>
    <visual>
      <origin xyz="0 0 0" rpy="0 0 0"/>
      <geometry>
        <mesh filename="model://iCubHeidelberg01_model/dae_meshes/weight-1kg_prt.dae" scale="0.001 0.001 0.001"/>
      </geometry>
      <material name="WEIGHT-1KG-2_color">
        <color rgba="0.666667 0.666667 0.666667 1.0"/>
      </material>
    </visual>
    <collision>
      <origin xyz="0 0 0" rpy="0 0 0"/>
      <geometry>
        <mesh filename="model://iCubHeidelberg01_model/dae_meshes/weight-1kg_prt.dae" scale="0.001 0.001 0.001"/>
      </geometry>
    </collision>
  </link>
  <joint name="chest_weight_3" type="fixed">
    <origin xyz="0 0.20675 0" rpy="1.57079632679 0 0"/>
    <parent link="chest"/>
    <child link="WEIGHT-1KG-2"/>
    <dynamics damping="0.1"/>
  </joint>
  <link name="WEIGHT-1KG-1">
    <inertial>
      <origin xyz="-1.00000000003e-06 1.46e-05 -1e-06" rpy="0 0 0"/>
      <mass value="1.00161"/>
      <inertia ixx="0.0010891" ixy="3.14425e-08" ixz="0.0" iyy="0.00108866" iyz="4.73842e-08" izz="0.00213553"/>
    </inertial>
    <visual>
      <origin xyz="0 0 0" rpy="0 0 0"/>
      <geometry>
        <mesh filename="model://iCubHeidelberg01_model/dae_meshes/weight-1kg_prt.dae" scale="0.001 0.001 0.001"/>
      </geometry>
      <material name="WEIGHT-1KG-1_color">
        <color rgba="0.666667 0.666667 0.666667 1.0"/>
      </material>
    </visual>
    <collision>
      <origin xyz="0 0 0" rpy="0 0 0"/>
      <geometry>
        <mesh filename="model://iCubHeidelberg01_model/dae_meshes/weight-1kg_prt.dae" scale="0.001 0.001 0.001"/>
      </geometry>
    </collision>
  </link>
  <joint name="chest_weight_2" type="fixed">
    <origin xyz="0.150750000191 0.0955 0" rpy="1.57079632679 0 -1.57079632679"/>
    <parent link="chest"/>
    <child link="WEIGHT-1KG-1"/>
    <dynamics damping="0.1"/>
  </joint>
  <gazebo reference="l_foot_ft_sensor">
       <sensor name='left_foot_ft' type='force_torque'>
                <force_torque>
                    <frame>sensor</frame>
                </force_torque>
                <always_on>1</always_on>
                <update_rate>100</update_rate>
                <pose>0 0 0 -1.577079 0 -1.577079</pose>
                <plugin name='left_foot_ft_plugin' filename='libgazebo_yarp_forcetorque.so'>
                    <yarpConfigurationFile>model://iCubHeidelberg01_model/conf/FT/gazebo_icub_left_foot_ft.ini</yarpConfigurationFile>
                </plugin>
            </sensor>
  </gazebo>
  <gazebo reference="r_foot_ft_sensor">
       <sensor name='right_foot_ft' type='force_torque'>
                <force_torque>
                    <frame>sensor</frame>
                </force_torque>
                <always_on>1</always_on>
                <update_rate>100</update_rate>
                <pose>0 0 0 -1.577079 0 -1.577079</pose>
                <plugin name='right_foot_ft_plugin' filename='libgazebo_yarp_forcetorque.so'>
                    <yarpConfigurationFile>model://iCubHeidelberg01_model/conf/FT/gazebo_icub_right_foot_ft.ini</yarpConfigurationFile>
                </plugin>
            </sensor>
  </gazebo>
  <gazebo reference="l_leg_ft_sensor">
       <sensor name='left_leg_ft' type='force_torque'>
                <force_torque>
                    <frame>sensor</frame>
                </force_torque>
                <always_on>1</always_on>
                <update_rate>100</update_rate>
                <pose>0 0 0 -1.577079 0 -1.577079</pose>
                <plugin name='left_leg_ft_plugin' filename='libgazebo_yarp_forcetorque.so'>
                    <yarpConfigurationFile>model://iCubHeidelberg01_model/conf/FT/gazebo_icub_left_leg_ft.ini</yarpConfigurationFile>
                </plugin>
       </sensor>
  </gazebo>
  <gazebo reference="r_leg_ft_sensor">
       <sensor name='right_leg_ft' type='force_torque'>
                <force_torque>
                    <frame>sensor</frame>
                </force_torque>
                <always_on>1</always_on>
                <update_rate>100</update_rate>
                <pose>0 0 0 -1.577079 0 -1.577079</pose>
                <plugin name='right_leg_ft_plugin' filename='libgazebo_yarp_forcetorque.so'>
                    <yarpConfigurationFile>model://iCubHeidelberg01_model/conf/FT/gazebo_icub_right_leg_ft.ini</yarpConfigurationFile>
                </plugin>
       </sensor>
  </gazebo>
</robot>

